<?xml version="1.0" ?>
<!-- 
  This is not a standalone urdf for neato. It simply defines the 'neato' tag that can
  be incorporated by other urdf files (e.g. turtlebot).
  
  See neato_standalone.urdf.xacro for a standalone urdf to be tested with
      neato_description/launch/view_model.launch
 -->
<robot name="neato" xmlns:xacro="http://ros.org/wiki/xacro">
  <xacro:include filename="$(find neato_description)/urdf/common_properties.urdf.xacro"/>
  <xacro:include filename="$(find neato_description)/urdf/neato_gazebo.urdf.xacro"/>
  
  <!-- neato --> 
  <xacro:macro name="neato">
	  <xacro:property name="camera_link" value="0.05" />

    <link name="base_footprint"/>
    <joint name="base_joint" type="fixed">
      <origin xyz="0 0 0" rpy="0 0 0" />
      <parent link="base_footprint"/>
      <child link="base_link" />
    </joint>
    <link name="base_link">
      <visual>
        <geometry>
          <mesh filename="package://neato_description/meshes/main_body.stl" scale="0.001 0.001 0.001"/>
        </geometry>
        <origin xyz="0 0 0" rpy="0 0 0"/>
        <material name="dark_grey"/>
      </visual>
      <collision>
        <geometry>
          <cylinder length="0.06" radius="0.15"/>
        </geometry>
        <origin xyz="-0.01 0 0.03" rpy="0 0 0"/>
      </collision>
      <collision>
        <geometry>
          <box size="0.16 0.3 0.06"/>
        </geometry>
        <origin xyz="0.08 0 0.03" rpy="0 0 0"/>
      </collision>
      <inertial>
        <origin xyz="0.01 0 0"/>
        <mass value="2.4"/>
        <inertia ixx="0.019995" ixy="0.0" ixz="0.0"
                 iyy="0.019995" iyz="0.0" 
                 izz="0.03675" />
      </inertial>
    </link>
    
    <joint name="wheel_left_joint" type="continuous">
      <parent link="base_link"/>
      <child link="wheel_left_link"/>
      <origin xyz="0.00 ${0.235/2} 0.0250" rpy="0 0 0"/>
      <axis xyz="0 1 0"/>
    </joint>
    <link name="wheel_left_link">
      <visual>
        <geometry>
          <mesh filename="package://neato_description/meshes/wheel.dae"/>
        </geometry>
        <origin xyz="0 0 0" rpy="${M_PI/2} 0 0"/>
      </visual>
      <collision>
        <geometry>
          <cylinder length="0.0206" radius="0.035"/>
        </geometry>
        <origin xyz="0 0 0" rpy="${M_PI/2} 0 0"/>
      </collision>
      <inertial>
        <mass value="0.01" />
        <origin xyz="0 0 0" />
        <inertia ixx="0.001" ixy="0.0" ixz="0.0"
                 iyy="0.001" iyz="0.0" 
                 izz="0.001" />
      </inertial>
    </link>
    
    <joint name="wheel_right_joint" type="continuous">
      <parent link="base_link"/>
      <child link="wheel_right_link"/>
      <origin xyz="0.00 -${0.235/2} 0.0250" rpy="0 0 0"/>
      <axis xyz="0 1 0"/>
    </joint>
    <link name="wheel_right_link">
      <visual>
        <geometry>
          <mesh filename="package://neato_description/meshes/wheel.dae"/>
        </geometry>
        <origin xyz="0 0 0" rpy="${M_PI/2} 0 0"/>
      </visual>
      <collision>
        <geometry>
          <cylinder length="0.0206" radius="0.035"/>
        </geometry>
        <origin xyz="0 0 0" rpy="${M_PI/2} 0 0"/>
      </collision>
      <inertial>
        <mass value="0.01" />
        <origin xyz="0 0 0" />
        <inertia ixx="0.001" ixy="0.0" ixz="0.0"
                 iyy="0.001" iyz="0.0" 
                 izz="0.001" />
      </inertial>
    </link>
    
    <joint name="caster_back_right_joint" type="fixed">
      <parent link="base_link"/>
      <child link="caster_back_right_link"/>
      <origin xyz="-0.11 -${0.18/2} 0" rpy="${M_PI/2} 0 0"/>
    </joint>
    <link name="caster_back_right_link">
      <collision>
        <geometry>
          <cylinder length="0.0176" radius="0.01"/>
        </geometry>
        <origin xyz="0 0 0" rpy="0 0 0"/>
      </collision>      
      <inertial>
        <mass value="0.01" />
        <origin xyz="0 0 0" />
        <inertia ixx="0.001" ixy="0.0" ixz="0.0"
                 iyy="0.001" iyz="0.0" 
                 izz="0.001" />
      </inertial>
    </link>
    
    <joint name="caster_back_left_joint" type="fixed">
      <parent link="base_link"/>
      <child link="caster_back_left_link"/>
      <origin xyz="-0.11 ${0.18/2} 0" rpy="${M_PI/2} 0 0"/>
    </joint>
    <link name="caster_back_left_link">
      <collision>
        <geometry>
          <cylinder length="0.0176" radius="0.01"/>
        </geometry>
        <origin xyz="0 0 0" rpy="0 0 0"/>
      </collision>      
      <inertial>
        <mass value="0.01" />
        <origin xyz="0 0 0" />
        <inertia ixx="0.001" ixy="0.0" ixz="0.0"
                 iyy="0.001" iyz="0.0" 
                 izz="0.001" />
      </inertial>
    </link>
    
    <joint name="caster_front_right_joint" type="fixed">
      <parent link="base_link"/>
      <child link="caster_front_right_link"/>
      <origin xyz="0.08 -${0.15/2} 0" rpy="${M_PI/2} 0 0"/>
    </joint>
    <link name="caster_front_right_link">
      <collision>
        <geometry>
          <cylinder length="0.0176" radius="0.01"/>
        </geometry>
        <origin xyz="0 0 0" rpy="0 0 0"/>
      </collision>      
      <inertial>
        <mass value="0.01" />
        <origin xyz="0 0 0" />
        <inertia ixx="0.001" ixy="0.0" ixz="0.0"
                 iyy="0.001" iyz="0.0" 
                 izz="0.001" />
      </inertial>
    </link>
    
    <joint name="caster_front_left_joint" type="fixed">
      <parent link="base_link"/>
      <child link="caster_front_left_link"/>
      <origin xyz="0.08 ${0.15/2} 0" rpy="${M_PI/2} 0 0"/>
    </joint>
    <link name="caster_front_left_link">
      <collision>
        <geometry>
          <cylinder length="0.0176" radius="0.01"/>
        </geometry>
        <origin xyz="0 0 0" rpy="0 0 0"/>
      </collision>      
      <inertial>
        <mass value="0.01" />
        <origin xyz="0 0 0" />
        <inertia ixx="0.001" ixy="0.0" ixz="0.0"
                 iyy="0.001" iyz="0.0" 
                 izz="0.001" />
      </inertial>
    </link>
    
    <!-- neato's sensors -->
    <joint name="imu_joint" type="fixed">
      <axis xyz="0 1 0"/>
      <origin xyz="0 0 0" rpy="0 0 0"/>
      <parent link="base_link"/>
      <child link="imu_link"/>
    </joint>
    <link name="imu_link">
      <inertial>
        <mass value="0.001"/>
        <origin xyz="0 0 0" rpy="0 0 0"/>
        <inertia ixx="0.0001" ixy="0" ixz="0" 
                 iyy="0.000001" iyz="0"
                 izz="0.0001"/>
      </inertial>
    </link>
    
    <joint name="cliff_sensor_right_joint" type="fixed">
      <origin xyz="0.11 -${0.29/2} 0" rpy="0 ${M_PI/2} 0" />
      <parent link="base_link"/>
      <child link="cliff_sensor_right_link" />
    </joint>
    <link name="cliff_sensor_right_link">
      <inertial>
        <mass value="0.0001" />
        <origin xyz="0 0 0" />
        <inertia ixx="0.0001" ixy="0.0" ixz="0.0"
                 iyy="0.0001" iyz="0.0" 
                 izz="0.0001" />
      </inertial>
    </link>
    
    <joint name="cliff_sensor_left_joint" type="fixed">
      <origin xyz="0.11 ${0.29/2} 0" rpy="0 ${M_PI/2} 0" />
      <parent link="base_link"/>
      <child link="cliff_sensor_left_link" />
    </joint>
    <link name="cliff_sensor_left_link">
      <inertial>
        <mass value="0.0001" />
        <origin xyz="0 0 0" />
        <inertia ixx="0.0001" ixy="0.0" ixz="0.0"
                 iyy="0.0001" iyz="0.0" 
                 izz="0.0001" />
      </inertial>
    </link>
    
    <joint name="laser_joint" type="fixed">
      <!-- Using a higher z origin than the physical robot due to erroneous self-collisions of 
	   laser with the body of the robot (as determined by the ROS Gazebo plugin) -->
      <origin xyz="-0.084 0 0.166" rpy="0 0 ${M_PI}" />
      <parent link="base_link"/>
      <child link="laser_link" />
    </joint>
    <link name="laser_link">
      <inertial>
        <mass value="0.0001" />
        <origin xyz="0 0 0"/>
        <inertia ixx="0.0001" ixy="0.0" ixz="0.0"
                 iyy="0.0001" iyz="0.0" 
                 izz="0.0001" />
      </inertial>
    </link>
<xacro:if value="$(arg load_camera)">
  <joint name="camera_joint" type="fixed">
    <axis xyz="0 1 0" />
    <origin xyz="-0.1 0 0.25" rpy="0 0 0"/>
    <parent link="base_link"/>
    <child link="camera_link"/>
  </joint>

  <link name="camera_link">
    <collision>
      <origin xyz="0 0 0" rpy="0 0 0"/>
      <geometry>
    <box size="${camera_link} ${camera_link} ${camera_link}"/>
      </geometry>
    </collision>

    <visual>
      <origin xyz="0 0 0" rpy="0 0 0"/>
      <geometry>
    <box size="${camera_link} ${camera_link} ${camera_link}"/>
      </geometry>
      <material name="red"/>
    </visual>

    <inertial>
      <mass value="1e-5" />
      <origin xyz="0 0 0" rpy="0 0 0"/>
      <inertia ixx="1e-6" ixy="0" ixz="0" iyy="1e-6" iyz="0" izz="1e-6" />
    </inertial>
  </link>
</xacro:if>
    <xacro:neato_sim/>
    
  </xacro:macro>
</robot>
