<sdf version='1.6'>
  <world name='default'>
    <light name='sun' type='directional'>
      <cast_shadows>1</cast_shadows>
      <pose frame=''>0 0 10 0 -0 0</pose>
      <diffuse>0.8 0.8 0.8 1</diffuse>
      <specular>0.2 0.2 0.2 1</specular>
      <attenuation>
        <range>1000</range>
        <constant>0.9</constant>
        <linear>0.01</linear>
        <quadratic>0.001</quadratic>
      </attenuation>
      <direction>-0.5 0.1 -0.9</direction>
    </light>
    <model name='ground_plane'>
      <static>1</static>
      <link name='link'>
        <collision name='collision'>
          <geometry>
            <plane>
              <normal>0 0 1</normal>
              <size>100 100</size>
            </plane>
          </geometry>
          <surface>
            <contact>
              <collide_bitmask>65535</collide_bitmask>
              <ode/>
            </contact>
            <friction>
              <ode>
                <mu>100</mu>
                <mu2>50</mu2>
              </ode>
              <torsional>
                <ode/>
              </torsional>
            </friction>
            <bounce/>
          </surface>
          <max_contacts>10</max_contacts>
        </collision>
        <visual name='visual'>
          <cast_shadows>0</cast_shadows>
          <geometry>
            <plane>
              <normal>0 0 1</normal>
              <size>100 100</size>
            </plane>
          </geometry>
          <material>
            <script>
              <uri>file://media/materials/scripts/gazebo.material</uri>
              <name>Gazebo/Grey</name>
            </script>
          </material>
        </visual>
        <self_collide>0</self_collide>
        <enable_wind>0</enable_wind>
        <kinematic>0</kinematic>
      </link>
    </model>
    <physics name='default_physics' default='0' type='ode'>
      <max_step_size>0.01</max_step_size>
      <real_time_factor>1</real_time_factor>
      <real_time_update_rate>100</real_time_update_rate>
    </physics>
    <gravity>0 0 -9.8</gravity>
    <magnetic_field>6e-06 2.3e-05 -4.2e-05</magnetic_field>
    <atmosphere type='adiabatic'/>
    <scene>
      <ambient>0.4 0.4 0.4 1</ambient>
      <background>0.7 0.7 0.7 1</background>
      <shadows>1</shadows>
    </scene>
    <audio>
      <device>default</device>
    </audio>
    <wind/>
    <spherical_coordinates>
      <surface_model>EARTH_WGS84</surface_model>
      <latitude_deg>0</latitude_deg>
      <longitude_deg>0</longitude_deg>
      <elevation>0</elevation>
      <heading_deg>0</heading_deg>
    </spherical_coordinates>
    <model name='mobile_base'>
      <link name='base_link'>
        <pose frame=''>0 0 0 0 -0 0</pose>
        <inertial>
          <pose frame=''>-1e-05 0 1e-06 0 -0 0</pose>
          <mass>10.003</mass>
          <inertia>
            <ixx>0.0802938</ixx>
            <ixy>0</ixy>
            <ixz>5.09021e-06</ixz>
            <iyy>0.0802646</iyy>
            <iyz>-3.36272e-19</iyz>
            <izz>0.144551</izz>
          </inertia>
        </inertial>
        <collision name='base_link_fixed_joint_lump__chassis_collision'>
          <pose frame=''>0 0 0 0 -0 0</pose>
          <geometry>
            <cylinder>
              <length>0.08</length>
              <radius>0.17</radius>
            </cylinder>
          </geometry>
          <surface>
            <contact>
              <ode/>
            </contact>
            <friction>
              <ode/>
              <torsional>
                <ode/>
              </torsional>
            </friction>
            <bounce/>
          </surface>
          <max_contacts>10</max_contacts>
        </collision>
        <collision name='base_link_fixed_joint_lump__left_axis_collision_1'>
          <pose frame=''>0 0.14 -0.02 -1.5708 0 0</pose>
          <geometry>
            <cylinder>
              <length>0.02</length>
              <radius>0.0025</radius>
            </cylinder>
          </geometry>
          <max_contacts>10</max_contacts>
          <surface>
            <contact>
              <ode/>
            </contact>
            <bounce/>
            <friction>
              <torsional>
                <ode/>
              </torsional>
              <ode/>
            </friction>
          </surface>
        </collision>
        <collision name='base_link_fixed_joint_lump__right_axis_collision_2'>
          <pose frame=''>0 -0.14 -0.02 -1.5708 0 0</pose>
          <geometry>
            <cylinder>
              <length>0.02</length>
              <radius>0.0025</radius>
            </cylinder>
          </geometry>
          <max_contacts>10</max_contacts>
          <surface>
            <contact>
              <ode/>
            </contact>
            <bounce/>
            <friction>
              <torsional>
                <ode/>
              </torsional>
              <ode/>
            </friction>
          </surface>
        </collision>
        <collision name='base_link_fixed_joint_lump__hokuyo_laser_link_collision_3'>
          <pose frame=''>-0.1016 0 0.0889 0 0 -3.14159</pose>
          <geometry>
            <cylinder>
              <length>0.04</length>
              <radius>0.045</radius>
            </cylinder>
          </geometry>
          <surface>
            <contact>
              <ode/>
            </contact>
            <friction>
              <ode/>
              <torsional>
                <ode/>
              </torsional>
            </friction>
            <bounce/>
          </surface>
          <max_contacts>10</max_contacts>
        </collision>
        <collision name='base_link_fixed_joint_lump__imu_sensor_link_collision_4'>
          <pose frame=''>-0.1 0 0.05 0 -0 0</pose>
          <geometry>
            <box>
              <size>0.02 0.02 0.02</size>
            </box>
          </geometry>
          <surface>
            <contact>
              <ode/>
            </contact>
            <friction>
              <ode/>
              <torsional>
                <ode/>
              </torsional>
            </friction>
            <bounce/>
          </surface>
          <max_contacts>10</max_contacts>
        </collision>
        <visual name='base_link_fixed_joint_lump__chassis_visual'>
          <pose frame=''>0 0 0 0 -0 0</pose>
          <geometry>
            <cylinder>
              <length>0.08</length>
              <radius>0.17</radius>
            </cylinder>
          </geometry>
          <material>
            <script>
              <name>Gazebo/Yellow</name>
              <uri>file://media/materials/scripts/gazebo.material</uri>
            </script>
          </material>
        </visual>
        <visual name='base_link_fixed_joint_lump__left_axis_visual_1'>
          <pose frame=''>0 0.14 -0.02 -1.5708 0 0</pose>
          <geometry>
            <cylinder>
              <length>0.02</length>
              <radius>0.0025</radius>
            </cylinder>
          </geometry>
        </visual>
        <visual name='base_link_fixed_joint_lump__right_axis_visual_2'>
          <pose frame=''>0 -0.14 -0.02 -1.5708 0 0</pose>
          <geometry>
            <cylinder>
              <length>0.02</length>
              <radius>0.0025</radius>
            </cylinder>
          </geometry>
        </visual>
        <visual name='base_link_fixed_joint_lump__hokuyo_laser_link_visual_3'>
          <pose frame=''>-0.1016 0 0.0889 0 0 -3.14159</pose>
          <geometry>
            <cylinder>
              <length>0.04</length>
              <radius>0.045</radius>
            </cylinder>
          </geometry>
          <material>
            <script>
              <uri>__default__</uri>
              <name>__default__</name>
            </script>
          </material>
        </visual>
        <visual name='base_link_fixed_joint_lump__imu_sensor_link_visual_4'>
          <pose frame=''>-0.1 0 0.05 0 -0 0</pose>
          <geometry>
            <box>
              <size>0.02 0.02 0.02</size>
            </box>
          </geometry>
          <material>
            <script>
              <uri>__default__</uri>
              <name>__default__</name>
            </script>
          </material>
        </visual>
        <velocity_decay/>
        <velocity_decay/>
        <gravity>1</gravity>
        <velocity_decay/>
        <gravity>1</gravity>
        <sensor name='head_hokuyo_sensor' type='ray'>
          <visualize>0</visualize>
          <update_rate>5</update_rate>
          <ray>
            <scan>
              <horizontal>
                <samples>361</samples>
                <resolution>1</resolution>
                <min_angle>-3.14159</min_angle>
                <max_angle>3.14159</max_angle>
              </horizontal>
              <vertical>
                <samples>1</samples>
                <min_angle>0</min_angle>
                <max_angle>0</max_angle>
              </vertical>
            </scan>
            <range>
              <min>0.2</min>
              <max>5</max>
              <resolution>0.36</resolution>
            </range>
            <noise>
              <type>gaussian</type>
              <mean>0</mean>
              <stddev>0.01</stddev>
            </noise>
          </ray>
          <plugin name='gazebo_ros_head_hokuyo_controller' filename='libgazebo_ros_laser.so'>
            <topicName>scan</topicName>
            <frameName>hokuyo_laser_link</frameName>
            <robotNamespace>/</robotNamespace>
          </plugin>
          <pose frame=''>-0.1016 0 0.0889 0 0 -3.14159</pose>
        </sensor>
        <gravity>1</gravity>
        <velocity_decay/>
        <gravity>1</gravity>
        <sensor name='imu_sensor' type='imu'>
          <always_on>1</always_on>
          <update_rate>100</update_rate>
          <visualize>1</visualize>
          <topic>__default_topic__</topic>
          <plugin name='imu_plugin' filename='libgazebo_ros_imu_sensor.so'>
            <topicName>imu_data</topicName>
            <bodyName>imu_sensor_link</bodyName>
            <updateRateHZ>10.0</updateRateHZ>
            <gaussianNoise>0.0</gaussianNoise>
            <xyzOffset>0 0 0</xyzOffset>
            <rpyOffset>0 0 0</rpyOffset>
            <frameName>base_link</frameName>
            <robotNamespace>/</robotNamespace>
          </plugin>
          <pose frame=''>-0.1 0 0.05 0 -0 0</pose>
          <imu/>
        </sensor>
        <self_collide>0</self_collide>
        <enable_wind>0</enable_wind>
        <kinematic>0</kinematic>
      </link>
      <link name='left_wheel_link'>
        <pose frame=''>0 0.14 -0.02 0 -0 0</pose>
        <inertial>
          <pose frame=''>0 0.01 0 -1.5708 0 0</pose>
          <mass>0.5</mass>
          <inertia>
            <ixx>0.000129167</ixx>
            <ixy>0</ixy>
            <ixz>0</ixz>
            <iyy>0.000129167</iyy>
            <iyz>0</iyz>
            <izz>3.75e-05</izz>
          </inertia>
        </inertial>
        <collision name='left_wheel_link_collision'>
          <pose frame=''>0 0 0 -1.5708 0 0</pose>
          <geometry>
            <cylinder>
              <length>0.02</length>
              <radius>0.03</radius>
            </cylinder>
          </geometry>
          <surface>
            <contact>
              <ode>
                <kp>1e+07</kp>
                <kd>1</kd>
                <min_depth>0.0001</min_depth>
              </ode>
            </contact>
            <friction>
              <ode>
                <mu>50</mu>
                <mu2>10</mu2>
                <fdir1>1 0 0</fdir1>
              </ode>
              <torsional>
                <ode/>
              </torsional>
            </friction>
            <bounce/>
          </surface>
          <max_contacts>1</max_contacts>
        </collision>
        <visual name='left_wheel_link_visual'>
          <pose frame=''>0 0 0 -1.5708 0 0</pose>
          <geometry>
            <cylinder>
              <length>0.02</length>
              <radius>0.03</radius>
            </cylinder>
          </geometry>
          <material>
            <script>
              <name>Gazebo/Grey</name>
              <uri>file://media/materials/scripts/gazebo.material</uri>
            </script>
          </material>
        </visual>
        <gravity>1</gravity>
        <velocity_decay/>
        <gravity>1</gravity>
        <self_collide>0</self_collide>
        <enable_wind>0</enable_wind>
        <kinematic>0</kinematic>
      </link>
      <joint name='left_wheel_rot_joint' type='revolute'>
        <child>left_wheel_link</child>
        <parent>base_link</parent>
        <axis>
          <xyz>0 1 0</xyz>
          <limit>
            <lower>-1e+16</lower>
            <upper>1e+16</upper>
          </limit>
          <dynamics>
            <spring_reference>0</spring_reference>
            <spring_stiffness>0</spring_stiffness>
          </dynamics>
          <use_parent_model_frame>1</use_parent_model_frame>
        </axis>
      </joint>
      <link name='right_wheel_link'>
        <pose frame=''>0 -0.14 -0.02 0 -0 0</pose>
        <inertial>
          <pose frame=''>0 0.01 0 -1.5708 0 0</pose>
          <mass>0.5</mass>
          <inertia>
            <ixx>0.000129167</ixx>
            <ixy>0</ixy>
            <ixz>0</ixz>
            <iyy>0.000129167</iyy>
            <iyz>0</iyz>
            <izz>3.75e-05</izz>
          </inertia>
        </inertial>
        <collision name='right_wheel_link_collision'>
          <pose frame=''>0 0 0 -1.5708 0 0</pose>
          <geometry>
            <cylinder>
              <length>0.02</length>
              <radius>0.03</radius>
            </cylinder>
          </geometry>
          <surface>
            <contact>
              <ode>
                <kp>1e+07</kp>
                <kd>1</kd>
                <min_depth>0.0001</min_depth>
              </ode>
            </contact>
            <friction>
              <ode>
                <mu>50</mu>
                <mu2>10</mu2>
                <fdir1>1 0 0</fdir1>
              </ode>
              <torsional>
                <ode/>
              </torsional>
            </friction>
            <bounce/>
          </surface>
          <max_contacts>1</max_contacts>
        </collision>
        <visual name='right_wheel_link_visual'>
          <pose frame=''>0 0 0 -1.5708 0 0</pose>
          <geometry>
            <cylinder>
              <length>0.02</length>
              <radius>0.03</radius>
            </cylinder>
          </geometry>
          <material>
            <script>
              <name>Gazebo/Grey</name>
              <uri>file://media/materials/scripts/gazebo.material</uri>
            </script>
          </material>
        </visual>
        <gravity>1</gravity>
        <velocity_decay/>
        <gravity>1</gravity>
        <self_collide>0</self_collide>
        <enable_wind>0</enable_wind>
        <kinematic>0</kinematic>
      </link>
      <joint name='right_wheel_rot_joint' type='revolute'>
        <child>right_wheel_link</child>
        <parent>base_link</parent>
        <axis>
          <xyz>0 1 0</xyz>
          <limit>
            <lower>-1e+16</lower>
            <upper>1e+16</upper>
          </limit>
          <dynamics>
            <spring_reference>0</spring_reference>
            <spring_stiffness>0</spring_stiffness>
          </dynamics>
          <use_parent_model_frame>1</use_parent_model_frame>
        </axis>
      </joint>
      <link name='sphere1'>
        <pose frame=''>0.14 0 -0.04 0 -0 0</pose>
        <inertial>
          <pose frame=''>0 0 0 0 -0 0</pose>
          <mass>0.3</mass>
          <inertia>
            <ixx>1.2e-05</ixx>
            <ixy>0</ixy>
            <ixz>0</ixz>
            <iyy>1.2e-05</iyy>
            <iyz>0</iyz>
            <izz>1.2e-05</izz>
          </inertia>
        </inertial>
        <collision name='sphere1_collision'>
          <pose frame=''>0 0 0 0 -0 0</pose>
          <geometry>
            <sphere>
              <radius>0.01</radius>
            </sphere>
          </geometry>
          <surface>
            <contact>
              <ode>
                <kp>1e+07</kp>
                <kd>1</kd>
                <min_depth>0.0001</min_depth>
              </ode>
            </contact>
            <friction>
              <ode>
                <mu>0</mu>
                <mu2>0</mu2>
                <fdir1>1 0 0</fdir1>
              </ode>
              <torsional>
                <ode/>
              </torsional>
            </friction>
            <bounce/>
          </surface>
          <max_contacts>1</max_contacts>
        </collision>
        <visual name='sphere1_visual'>
          <pose frame=''>0 0 0 0 -0 0</pose>
          <geometry>
            <sphere>
              <radius>0.01</radius>
            </sphere>
          </geometry>
          <material>
            <script>
              <name>Gazebo/Grey</name>
              <uri>file://media/materials/scripts/gazebo.material</uri>
            </script>
          </material>
        </visual>
        <gravity>1</gravity>
        <velocity_decay/>
        <gravity>1</gravity>
        <self_collide>0</self_collide>
        <enable_wind>0</enable_wind>
        <kinematic>0</kinematic>
      </link>
      <joint name='sphere_joint1' type='revolute'>
        <child>sphere1</child>
        <parent>base_link</parent>
        <axis>
          <xyz>0 0 1</xyz>
          <limit>
            <lower>0</lower>
            <upper>0</upper>
            <effort>100</effort>
            <velocity>100</velocity>
          </limit>
          <dynamics>
            <spring_reference>0</spring_reference>
            <spring_stiffness>0</spring_stiffness>
          </dynamics>
          <use_parent_model_frame>1</use_parent_model_frame>
        </axis>
      </joint>
      <link name='sphere2'>
        <pose frame=''>-0.14 0 -0.04 0 -0 0</pose>
        <inertial>
          <pose frame=''>0 0 0 0 -0 0</pose>
          <mass>0.3</mass>
          <inertia>
            <ixx>1.2e-05</ixx>
            <ixy>0</ixy>
            <ixz>0</ixz>
            <iyy>1.2e-05</iyy>
            <iyz>0</iyz>
            <izz>1.2e-05</izz>
          </inertia>
        </inertial>
        <collision name='sphere2_collision'>
          <pose frame=''>0 0 0 0 -0 0</pose>
          <geometry>
            <sphere>
              <radius>0.01</radius>
            </sphere>
          </geometry>
          <surface>
            <contact>
              <ode>
                <kp>1e+07</kp>
                <kd>1</kd>
                <min_depth>0.0001</min_depth>
              </ode>
            </contact>
            <friction>
              <ode>
                <mu>0</mu>
                <mu2>0</mu2>
                <fdir1>1 0 0</fdir1>
              </ode>
              <torsional>
                <ode/>
              </torsional>
            </friction>
            <bounce/>
          </surface>
          <max_contacts>1</max_contacts>
        </collision>
        <visual name='sphere2_visual'>
          <pose frame=''>0 0 0 0 -0 0</pose>
          <geometry>
            <sphere>
              <radius>0.01</radius>
            </sphere>
          </geometry>
          <material>
            <script>
              <name>Gazebo/Grey</name>
              <uri>file://media/materials/scripts/gazebo.material</uri>
            </script>
          </material>
        </visual>
        <gravity>1</gravity>
        <velocity_decay/>
        <gravity>1</gravity>
        <self_collide>0</self_collide>
        <enable_wind>0</enable_wind>
        <kinematic>0</kinematic>
      </link>
      <joint name='sphere_joint2' type='revolute'>
        <child>sphere2</child>
        <parent>base_link</parent>
        <axis>
          <xyz>0 0 1</xyz>
          <limit>
            <lower>0</lower>
            <upper>0</upper>
            <effort>100</effort>
            <velocity>100</velocity>
          </limit>
          <dynamics>
            <spring_reference>0</spring_reference>
            <spring_stiffness>0</spring_stiffness>
          </dynamics>
          <use_parent_model_frame>1</use_parent_model_frame>
        </axis>
      </joint>
      <static>0</static>
      <plugin name='differential_drive_controller' filename='libgazebo_ros_diff_drive.so'>
        <rosDebugLevel>Debug</rosDebugLevel>
        <publishWheelTF>0</publishWheelTF>
        <publishWheelJointState>1</publishWheelJointState>
        <alwaysOn>1</alwaysOn>
        <leftJoint>left_wheel_rot_joint</leftJoint>
        <rightJoint>right_wheel_rot_joint</rightJoint>
        <wheelSeparation>0.28</wheelSeparation>
        <wheelDiameter>0.06</wheelDiameter>
        <torque>20</torque> <wheelAcceleration>1.8</wheelAcceleration> <commandTopic>cmd_vel</commandTopic> <odometryTopic>odom</odometryTopic>
        <odometryFrame>odom</odometryFrame>
        <odometrySource>encoder</odometrySource>
        <robotBaseFrame>base_link</robotBaseFrame>
        <updateRate>10.0</updateRate>
        <legacyMode>0</legacyMode>
        <robotNamespace>/</robotNamespace>
      </plugin>
      <plugin name='joint_state_publisher' filename='libgazebo_ros_joint_state_publisher.so'>
        <jointName>left_wheel_rot_joint, right_wheel_rot_joint</jointName>
        <updateRate>10.0</updateRate>
        <alwaysOn>1</alwaysOn>
        <robotNamespace>/</robotNamespace>
      </plugin>
      <plugin name='imu_plugin' filename='libgazebo_ros_imu.so'>
        <bodyName>base_link</bodyName>
        <updateRate>100.0</updateRate>
        <topicName>imu_data</topicName>
        <serviceName>imu_service</serviceName>
        <gaussianNoise>0.1</gaussianNoise>
        <xyzOffset>0 0 0</xyzOffset>
        <rpyOffset>0 0 0</rpyOffset>
        <robotNamespace>/</robotNamespace>
      </plugin>
      <pose frame=''>0.018 0.142469 1 0 -0  0</pose>
    </model>



  <model name="new_plane">
<pose frame=''>0.157031 2.196181 0 0 0 0.214496</pose>	
    <static>true</static>
    <link name="link">
	    <collision name="collision">
<geometry>
<polyline>
<point>-0.58182 -1.6637</point>
<point>-1.5402 -1.3782</point>
<point>-1.7115 -1.9532</point>
<point>-0.75311 -2.2387</point>
<point>-0.62774 -2.2658</point>
<point>-0.49758 -2.2781</point>
<point>-0.35995 -2.2793</point>
<point>-0.21498 -2.2707</point>
<point>-0.064392 -2.2528</point>
<point>0.089291 -2.2256</point>
<point>0.2432 -2.1888</point>
<point>0.39447 -2.142</point>
<point>0.54046 -2.084</point>
<point>0.67883 -2.013</point>
<point>0.8072 -1.9258</point>
<point>0.92186 -1.8175</point>
<point>1.0153 -1.6838</point>
<point>1.0751 -1.526</point>
<point>1.0916 -1.3569</point>
<point>1.0666 -1.1926</point>
<point>1.0099 -1.0404</point>
<point>0.93031 -0.89883</point>
<point>0.8332 -0.76432</point>
<point>0.72191 -0.63368</point>
<point>0.59936 -0.50497</point>
<point>0.46862 -0.37718</point>
<point>0.33314 -0.24998</point>
<point>0.19669 -0.12349</point>
<point>0.063264 0.0018298</point>
<point>-0.063042 0.12519</point>
<point>-0.1782 0.24549</point>
<point>-0.27845 0.3612</point>
<point>-0.36059 0.47033</point>
<point>-0.42242 0.57043</point>
<point>-0.46343 0.65887</point>
<point>-0.48538 0.73396</point>
<point>-0.492 0.79692</point>
<point>-0.48657 0.85306</point>
<point>-0.46904 0.90977</point>
<point>-0.4361 0.97214</point>
<point>-0.38441 1.0409</point>
<point>-0.31292 1.1142</point>
<point>-0.22302 1.1889</point>
<point>-0.11777 1.2627</point>
<point>-0.0011167 1.3336</point>
<point>0.12258 1.4001</point>
<point>0.24878 1.4612</point>
<point>0.37301 1.5161</point>
<point>0.49091 1.5642</point>
<point>0.59837 1.605</point>
<point>0.69153 1.6381</point>
<point>0.76669 1.663</point>
<point>0.81955 1.6792</point>
<point>0.65357 2.2558</point>
<point>0.58417 2.2346</point>
<point>0.49672 2.2056</point>
<point>0.39177 2.1683</point>
<point>0.27153 2.1226</point>
<point>0.13896 2.0686</point>
<point>-0.0025869 2.006</point>
<point>-0.14951 1.9348</point>
<point>-0.29814 1.8549</point>
<point>-0.44486 1.7657</point>
<point>-0.58618 1.6665</point>
<point>-0.71868 1.5561</point>
<point>-0.83876 1.4328</point>
<point>-0.94211 1.2946</point>
<point>-1.023 1.1402</point>
<point>-1.0748 0.97143</point>
<point>-1.092 0.79431</point>
<point>-1.0739 0.61722</point>
<point>-1.0246 0.44652</point>
<point>-0.94988 0.28445</point>
<point>-0.85499 0.13039</point>
<point>-0.74409 -0.017194</point>
<point>-0.62075 -0.15967</point>
<point>-0.48845 -0.29793</point>
<point>-0.35082 -0.43238</point>
<point>-0.21172 -0.56304</point>
<point>-0.075196 -0.6896</point>
<point>0.054594 -0.81144</point>
<point>0.1735 -0.92763</point>
<point>0.27749 -1.0368</point>
<point>0.36289 -1.1369</point>
<point>0.42673 -1.225</point>
<point>0.46759 -1.2971</point>
<point>0.48716 -1.3484</point>
<point>0.49196 -1.3769</point>
<point>0.49099 -1.389</point>
<point>0.48663 -1.3999</point>
<point>0.47092 -1.4217</point>
<point>0.43485 -1.4553</point>
<point>0.37539 -1.4954</point>
<point>0.29443 -1.5367</point>
<point>0.19616 -1.5757</point>
<point>0.085511 -1.6099</point>
<point>-0.032313 -1.6381</point>
<point>-0.15207 -1.6593</point>
<point>-0.26845 -1.6731</point>
<point>-0.376 -1.6795</point>
<point>-0.46891 -1.6787</point>
<point>-0.54043 -1.6722</point>
<point>-0.58182 -1.6637</point>
<height>0.5</height>
</polyline>
</geometry>
        <surface>
          <contact>
             <collide_bitmask>0xffff</collide_bitmask>
          </contact>
          <friction>
            <ode>
              <mu>100</mu>
              <mu2>50</mu2>
            </ode>
          </friction>
        </surface>
      </collision>
      <visual name="visual">
<geometry>
<polyline>
<point>-0.58182 -1.6637</point>
<point>-1.5402 -1.3782</point>
<point>-1.7115 -1.9532</point>
<point>-0.75311 -2.2387</point>
<point>-0.62774 -2.2658</point>
<point>-0.49758 -2.2781</point>
<point>-0.35995 -2.2793</point>
<point>-0.21498 -2.2707</point>
<point>-0.064392 -2.2528</point>
<point>0.089291 -2.2256</point>
<point>0.2432 -2.1888</point>
<point>0.39447 -2.142</point>
<point>0.54046 -2.084</point>
<point>0.67883 -2.013</point>
<point>0.8072 -1.9258</point>
<point>0.92186 -1.8175</point>
<point>1.0153 -1.6838</point>
<point>1.0751 -1.526</point>
<point>1.0916 -1.3569</point>
<point>1.0666 -1.1926</point>
<point>1.0099 -1.0404</point>
<point>0.93031 -0.89883</point>
<point>0.8332 -0.76432</point>
<point>0.72191 -0.63368</point>
<point>0.59936 -0.50497</point>
<point>0.46862 -0.37718</point>
<point>0.33314 -0.24998</point>
<point>0.19669 -0.12349</point>
<point>0.063264 0.0018298</point>
<point>-0.063042 0.12519</point>
<point>-0.1782 0.24549</point>
<point>-0.27845 0.3612</point>
<point>-0.36059 0.47033</point>
<point>-0.42242 0.57043</point>
<point>-0.46343 0.65887</point>
<point>-0.48538 0.73396</point>
<point>-0.492 0.79692</point>
<point>-0.48657 0.85306</point>
<point>-0.46904 0.90977</point>
<point>-0.4361 0.97214</point>
<point>-0.38441 1.0409</point>
<point>-0.31292 1.1142</point>
<point>-0.22302 1.1889</point>
<point>-0.11777 1.2627</point>
<point>-0.0011167 1.3336</point>
<point>0.12258 1.4001</point>
<point>0.24878 1.4612</point>
<point>0.37301 1.5161</point>
<point>0.49091 1.5642</point>
<point>0.59837 1.605</point>
<point>0.69153 1.6381</point>
<point>0.76669 1.663</point>
<point>0.81955 1.6792</point>
<point>0.65357 2.2558</point>
<point>0.58417 2.2346</point>
<point>0.49672 2.2056</point>
<point>0.39177 2.1683</point>
<point>0.27153 2.1226</point>
<point>0.13896 2.0686</point>
<point>-0.0025869 2.006</point>
<point>-0.14951 1.9348</point>
<point>-0.29814 1.8549</point>
<point>-0.44486 1.7657</point>
<point>-0.58618 1.6665</point>
<point>-0.71868 1.5561</point>
<point>-0.83876 1.4328</point>
<point>-0.94211 1.2946</point>
<point>-1.023 1.1402</point>
<point>-1.0748 0.97143</point>
<point>-1.092 0.79431</point>
<point>-1.0739 0.61722</point>
<point>-1.0246 0.44652</point>
<point>-0.94988 0.28445</point>
<point>-0.85499 0.13039</point>
<point>-0.74409 -0.017194</point>
<point>-0.62075 -0.15967</point>
<point>-0.48845 -0.29793</point>
<point>-0.35082 -0.43238</point>
<point>-0.21172 -0.56304</point>
<point>-0.075196 -0.6896</point>
<point>0.054594 -0.81144</point>
<point>0.1735 -0.92763</point>
<point>0.27749 -1.0368</point>
<point>0.36289 -1.1369</point>
<point>0.42673 -1.225</point>
<point>0.46759 -1.2971</point>
<point>0.48716 -1.3484</point>
<point>0.49196 -1.3769</point>
<point>0.49099 -1.389</point>
<point>0.48663 -1.3999</point>
<point>0.47092 -1.4217</point>
<point>0.43485 -1.4553</point>
<point>0.37539 -1.4954</point>
<point>0.29443 -1.5367</point>
<point>0.19616 -1.5757</point>
<point>0.085511 -1.6099</point>
<point>-0.032313 -1.6381</point>
<point>-0.15207 -1.6593</point>
<point>-0.26845 -1.6731</point>
<point>-0.376 -1.6795</point>
<point>-0.46891 -1.6787</point>
<point>-0.54043 -1.6722</point>
<point>-0.58182 -1.6637</point>
<height>0.5</height>
</polyline>
</geometry>
          <material>
            <script>
              <uri>file://media/materials/scripts/gazebo.material</uri>
              <name>Gazebo/Blue</name>
            </script>
          </material>
      </visual>
    </link>
  </model>


    <state world_name='default'>
      <sim_time>172 370000000</sim_time>
      <real_time>336 650258503</real_time>
      <wall_time>1583526667 499296729</wall_time>
      <iterations>17237</iterations>
      <model name='ground_plane'>
        <pose frame=''>0 0 0 0 -0 0</pose>
        <scale>1 1 1</scale>
        <link name='link'>
          <pose frame=''>0 0 0 0 -0 0</pose>
          <velocity>0 0 0 0 -0 0</velocity>
          <acceleration>0 0 0 0 -0 0</acceleration>
          <wrench>0 0 0 0 -0 0</wrench>
        </link>
      </model>
      <light name='sun'>
        <pose frame=''>0 0 10 0 -0 0</pose>
      </light>
    </state>
    <gui fullscreen='0'>
      <camera name='user_camera'>
        <pose frame=''>1.17114 -0.666603 2.35243 -0 1.00239 2.64819</pose>
        <view_controller>orbit</view_controller>
        <projection_type>perspective</projection_type>
      </camera>
    </gui>
  </world>
</sdf>
